Processamento: 08-20-2020 13:50:02
Dados coletados em: https://www.vs.saude.ms.gov.br/wp-content/uploads/2020/08/Microdados-2020.08.20.csv
Data: 2020-08-20
Traceback (most recent call last):
  File "/home/boselli/Marco/prog/epidemia/microdados_ms/dados_git/agregate_gh.py", line 31, in <module>
    df = pd.read_csv(csv_url, sep =';', usecols=cols_list)
  File "/usr/lib64/python3.6/site-packages/pandas/io/parsers.py", line 676, in parser_f
    return _read(filepath_or_buffer, kwds)
  File "/usr/lib64/python3.6/site-packages/pandas/io/parsers.py", line 448, in _read
    parser = TextFileReader(fp_or_buf, **kwds)
  File "/usr/lib64/python3.6/site-packages/pandas/io/parsers.py", line 880, in __init__
    self._make_engine(self.engine)
  File "/usr/lib64/python3.6/site-packages/pandas/io/parsers.py", line 1114, in _make_engine
    self._engine = CParserWrapper(self.f, **self.options)
  File "/usr/lib64/python3.6/site-packages/pandas/io/parsers.py", line 1891, in __init__
    self._reader = parsers.TextReader(src, **kwds)
  File "pandas/_libs/parsers.pyx", line 529, in pandas._libs.parsers.TextReader.__cinit__
  File "pandas/_libs/parsers.pyx", line 749, in pandas._libs.parsers.TextReader._get_header
UnicodeDecodeError: 'utf-8' codec can't decode byte 0xcd in position 5: invalid continuation byte
