Processamento: 11-30-2020 13:50:02
Dados coletados em: https://www.vs.saude.ms.gov.br/wp-content/uploads/2020/11/Microdados-2020.11.30.csv
Data: 2020-11-30
Traceback (most recent call last):
  File "/home/boselli/Marco/prog/epidemia/microdados_ms/dados_git/agregate_gh.py", line 31, in <module>
    df = pd.read_csv(csv_url, sep =';', usecols=cols_list)
  File "/usr/lib64/python3.6/site-packages/pandas/io/parsers.py", line 676, in parser_f
    return _read(filepath_or_buffer, kwds)
  File "/usr/lib64/python3.6/site-packages/pandas/io/parsers.py", line 431, in _read
    filepath_or_buffer, encoding, compression
  File "/usr/lib64/python3.6/site-packages/pandas/io/common.py", line 172, in get_filepath_or_buffer
    req = urlopen(filepath_or_buffer)
  File "/usr/lib64/python3.6/site-packages/pandas/io/common.py", line 141, in urlopen
    return urllib.request.urlopen(*args, **kwargs)
  File "/usr/lib64/python3.6/urllib/request.py", line 223, in urlopen
    return opener.open(url, data, timeout)
  File "/usr/lib64/python3.6/urllib/request.py", line 532, in open
    response = meth(req, response)
  File "/usr/lib64/python3.6/urllib/request.py", line 642, in http_response
    'http', request, response, code, msg, hdrs)
  File "/usr/lib64/python3.6/urllib/request.py", line 570, in error
    return self._call_chain(*args)
  File "/usr/lib64/python3.6/urllib/request.py", line 504, in _call_chain
    result = func(*args)
  File "/usr/lib64/python3.6/urllib/request.py", line 650, in http_error_default
    raise HTTPError(req.full_url, code, msg, hdrs, fp)
urllib.error.HTTPError: HTTP Error 404: Not Found
